Workbook

Sheet The Raw Data 
B3: Income statement(£m)
C5: 2020 | D5: 2021 | E5: 2022 | F5: 2023
B6: Revenue | C6: 33014 | D6: 38655 | E6: 43004 | F6: 45754
B7: Operating profit | C7: 8997 | D7: 10308 | E7: 10909 | F7: 11311
B8: Financal costs | C8: 1437 | D8: 1597 | E8: 882 | F8: 1527
B9: net profit | C9: 9804 | D9: 7768 | E9: 9571 | F9: 10703
B10: Cost of sales | C10: 13433 | D10: 15357 | E10: 18000 | F10: 18520
B14: Balance sheet (£m) except in number of shares
C16: 2020 | D16: 2021 | E16: 2022 | F16: 2023
B17: Current assets | C17: 19240 | D17: 22545 | E17: 22591 | F17: 26732
B18: Noncurrent sssets | C18: 68054 | D18: 71809 | E18: 70172 | F18: 70971
B19: current liabilities | C19: 14601 | D19: 19950 | E19: 19724 | F19: 23571
B20: non current liabilities | C20: 51411 | D20: 49544 | E20: 47213 | F20: 46649
B21: equity | C21: 21284 | D21: 24860 | E21: 25826 | F21: 27480
B23: Receivables | C23: 3144 | D23: 3512 | E23: 3487 | F23: 3410
B24: inventories | C24: 3266 | D24: 3414 | E24: 4233 | F24: 4424
B25: Payables | C25: 11145 | D25: 14619 | E25: 15749 | F25: 15485
B26: Number of shares | C26: 7040 | D26: 7040 | E26: 7040 | F26: 7040
B27: Dividend paid | C27: 7047 | D27: 7252 | E27: 7616 | F27: 7952

Sheet Overview
B3: Income statement
C5: 2020 | D5: 2021 | E5: % change | F5: 2022 | G5: % change | H5: 2023 | I5: % change
B6: Revenue | C6: ='The Raw Data '!C6 -> 33014 | D6: ='The Raw Data '!D6 -> 38655 | E6: =(D6-C6)/C6 -> 0.1708669 | F6: ='The Raw Data '!E6 -> 43004 | G6: =(F6-D6)/D6 -> 0.11250808 | H6: ='The Raw Data '!F6 -> 45754 | I6: =(H6-F6)/F6 -> 0.06394754
B7: Operating profit | C7: ='The Raw Data '!C7 -> 8997 | D7: ='The Raw Data '!D7 -> 10308 | E7: =(D7-C7)/C7 -> 0.14571524 | F7: ='The Raw Data '!E7 -> 10909 | G7: =(F7-D7)/D7 -> 0.05830423 | H7: ='The Raw Data '!F7 -> 11311 | I7: =(H7-F7)/F7 -> 0.036850307
B8: Financal costs | C8: ='The Raw Data '!C8 -> 1437 | D8: ='The Raw Data '!D8 -> 1597 | E8: =(D8-C8)/C8 -> 0.11134308 | F8: ='The Raw Data '!E8 -> 882 | G8: =(F8-D8)/D8 -> -0.44771446 | H8: ='The Raw Data '!F8 -> 1527 | I8: =(H8-F8)/F8 -> 0.73129252
B9: net profit | C9: ='The Raw Data '!C9 -> 9804 | D9: ='The Raw Data '!D9 -> 7768 | E9: =(D9-C9)/C9 -> -0.20767034 | F9: ='The Raw Data '!E9 -> 9571 | G9: =(F9-D9)/D9 -> 0.23210608 | H9: ='The Raw Data '!F9 -> 10703 | I9: =(H9-F9)/F9 -> 0.11827395
B10: Cost of sales | C10: ='The Raw Data '!C10 -> 13433 | D10: ='The Raw Data '!D10 -> 15357 | E10: =(D10-C10)/C10 -> 0.14322936 | F10: ='The Raw Data '!E10 -> 18000 | G10: =(F10-D10)/D10 -> 0.17210393 | H10: ='The Raw Data '!F10 -> 18520 | I10: =(H10-F10)/F10 -> 0.028888889
B14: Balance sheet
C16: 2020 | D16: 2021 | E16: % change | F16: 2022 | G16: % change | H16: 2023 | I16: % change
B17: Current assets | C17: ='The Raw Data '!C17 -> 19240 | D17: ='The Raw Data '!D17 -> 22545 | E17: =(D17-C17)/C17 -> 0.17177755 | F17: ='The Raw Data '!E17 -> 22591 | G17: =(F17-D17)/D17 -> 0.0020403637 | H17: ='The Raw Data '!F17 -> 26732 | I17: =(H17-F17)/F17 -> 0.18330309
B18: Noncurrent sssets | C18: ='The Raw Data '!C18 -> 68054 | D18: ='The Raw Data '!D18 -> 71809 | E18: =(D18-C18)/C18 -> 0.055176771 | F18: ='The Raw Data '!E18 -> 70172 | G18: =(F18-D18)/D18 -> -0.022796585 | H18: ='The Raw Data '!F18 -> 70971 | I18: =(H18-F18)/F18 -> 0.011386308
B19: current liabilities | C19: ='The Raw Data '!C19 -> 14601 | D19: ='The Raw Data '!D19 -> 19950 | E19: =(D19-C19)/C19 -> 0.36634477 | F19: ='The Raw Data '!E19 -> 19724 | G19: =(F19-D19)/D19 -> -0.011328321 | H19: ='The Raw Data '!F19 -> 23571 | I19: =(H19-F19)/F19 -> 0.19504157
B20: non current liabilities | C20: ='The Raw Data '!C20 -> 51411 | D20: ='The Raw Data '!D20 -> 49544 | E20: =(D20-C20)/C20 -> -0.036315185 | F20: ='The Raw Data '!E20 -> 47213 | G20: =(F20-D20)/D20 -> -0.047049088 | H20: ='The Raw Data '!F20 -> 46649 | I20: =(H20-F20)/F20 -> -0.011945862
B21: equity | C21: ='The Raw Data '!C21 -> 21284 | D21: ='The Raw Data '!D21 -> 24860 | E21: =(D21-C21)/C21 -> 0.16801353 | F21: ='The Raw Data '!E21 -> 25826 | G21: =(F21-D21)/D21 -> 0.038857603 | H21: ='The Raw Data '!F21 -> 27480 | I21: =(H21-F21)/F21 -> 0.064043987

Sheet Ratio Calculations
F4: 2020 | G4: 2021 | H4: 2022 | I4: 2023 | N4: Income statement(£m)
C5: Profitability
C6: Return on Capital Employed | D6: Operating Profit (PBIT) x 100 Total Asset - current liabilities | E6: Operating profit (Earnings from Operations) | F6: =O8 -> 8997 | G6: =P8 -> 10308 | H6: =Q8 -> 10909 | I6: =R8 -> 11311 | O6: 2020 | P6: 2021 | Q6: 2022 | R6: 2023
E7: Total Assets | F7: =O18+O19 -> 87294 | G7: =P18+P19 -> 94354 | H7: =Q18+Q19 -> 92763 | I7: =R18+R19 -> 97703 | N7: Revenue | O7: ='The Raw Data '!C6 -> 33014 | P7: ='The Raw Data '!D6 -> 38655 | Q7: ='The Raw Data '!E6 -> 43004 | R7: ='The Raw Data '!F6 -> 45754
E8: Current liabilities | F8: =O20 -> 14601 | G8: =P20 -> 19950 | H8: =Q20 -> 19724 | I8: =R20 -> 23571 | N8: Operating profit | O8: ='The Raw Data '!C7 -> 8997 | P8: ='The Raw Data '!D7 -> 10308 | Q8: ='The Raw Data '!E7 -> 10909 | R8: ='The Raw Data '!F7 -> 11311
F9: =F6/(F7-F8) -> 0.12376708 | G9: =G6/(G7-G8) -> 0.13854094 | H9: =H6/(H7-H8) -> 0.14935856 | I9: =I6/(I7-I8) -> 0.15257918 | N9: Financal costs | O9: ='The Raw Data '!C8 -> 1437 | P9: ='The Raw Data '!D8 -> 1597 | Q9: ='The Raw Data '!E8 -> 882 | R9: ='The Raw Data '!F8 -> 1527
N10: net profit | O10: ='The Raw Data '!C9 -> 9804 | P10: ='The Raw Data '!D9 -> 7768 | Q10: ='The Raw Data '!E9 -> 9571 | R10: ='The Raw Data '!F9 -> 10703
C11: Operating profit margin | D11: Operating Profit x 100 Total Revenue | E11: Operating profit (Earnings from Operations) | F11: =O8 -> 8997 | G11: =P8 -> 10308 | H11: =Q8 -> 10909 | I11: =R8 -> 11311 | N11: Cost of sales | O11: ='The Raw Data '!C10 -> 13433 | P11: ='The Raw Data '!D10 -> 15357 | Q11: ='The Raw Data '!E10 -> 18000 | R11: ='The Raw Data '!F10 -> 18520
E12: Total Revenue | F12: =O7 -> 33014 | G12: =P7 -> 38655 | H12: =Q7 -> 43004 | I12: =R7 -> 45754
F13: =F11/F12 -> 0.27252075 | G13: =G11/G12 -> 0.26666667 | H13: =H11/H12 -> 0.25367408 | I13: =I11/I12 -> 0.24721336
C15: Return on Assets | D15: Net profit (profit for the year) x 100 Total Assets | E15: Net profit/loss | F15: =O10 -> 9804 | G15: =P10 -> 7768 | H15: =Q10 -> 9571 | I15: =R10 -> 10703 | N15: Balance sheet (£m) except in number of shares
E16: Total Assets | F16: =O18+O19 -> 87294 | G16: =P18+P19 -> 94354 | H16: =Q18+Q19 -> 92763 | I16: =R18+R19 -> 97703
F17: =F15/F16 -> 0.11231012 | G17: =G15/G16 -> 0.082328253 | H17: =H15/H16 -> 0.10317691 | I17: =I15/I16 -> 0.10954628 | O17: 2020 | P17: 2021 | Q17: 2022 | R17: 2023
N18: Current assets | O18: ='The Raw Data '!C17 -> 19240 | P18: ='The Raw Data '!D17 -> 22545 | Q18: ='The Raw Data '!E17 -> 22591 | R18: ='The Raw Data '!F17 -> 26732
C19: Liquidity Ratio | N19: Noncurrent sssets | O19: ='The Raw Data '!C18 -> 68054 | P19: ='The Raw Data '!D18 -> 71809 | Q19: ='The Raw Data '!E18 -> 70172 | R19: ='The Raw Data '!F18 -> 70971
C20: Current Ratio (expressed as a ratio X:Y) | D20: Current Asset Current Liabilities | E20: Current Asset | F20: =O18 -> 19240 | G20: =P18 -> 22545 | H20: =Q18 -> 22591 | I20: =R18 -> 26732 | N20: current liabilities | O20: ='The Raw Data '!C19 -> 14601 | P20: ='The Raw Data '!D19 -> 19950 | Q20: ='The Raw Data '!E19 -> 19724 | R20: ='The Raw Data '!F19 -> 23571
E21: Current Liabilities | F21: =O20 -> 14601 | G21: =P20 -> 19950 | H21: =Q20 -> 19724 | I21: =R20 -> 23571 | N21: non current liabilities | O21: ='The Raw Data '!C20 -> 51411 | P21: ='The Raw Data '!D20 -> 49544 | Q21: ='The Raw Data '!E20 -> 47213 | R21: ='The Raw Data '!F20 -> 46649
F22: =F20/F21 -> 1.317718 | G22: =G20/G21 -> 1.1300752 | H22: =H20/H21 -> 1.1453559 | I22: =I20/I21 -> 1.1341055 | N22: equity | O22: ='The Raw Data '!C21 -> 21284 | P22: ='The Raw Data '!D21 -> 24860 | Q22: ='The Raw Data '!E21 -> 25826 | R22: ='The Raw Data '!F21 -> 27480
C24: Quick Ratio (expressed as a ratio X:Y) | D24: (Current Asset - inventories) Current Liabilities | E24: Current Asset | F24: =O18 -> 19240 | G24: =P18 -> 22545 | H24: =Q18 -> 22591 | I24: =R18 -> 26732 | N24: Receivables | O24: ='The Raw Data '!C23 -> 3144 | P24: ='The Raw Data '!D23 -> 3512 | Q24: ='The Raw Data '!E23 -> 3487 | R24: ='The Raw Data '!F23 -> 3410
E25: Inventories | F25: =O25 -> 3266 | G25: =P25 -> 3414 | H25: =Q25 -> 4233 | I25: =R25 -> 4424 | N25: inventories | O25: ='The Raw Data '!C24 -> 3266 | P25: ='The Raw Data '!D24 -> 3414 | Q25: ='The Raw Data '!E24 -> 4233 | R25: ='The Raw Data '!F24 -> 4424
E26: Current Liabilities | F26: =O20 -> 14601 | G26: =P20 -> 19950 | H26: =Q20 -> 19724 | I26: =R20 -> 23571 | N26: Payables | O26: ='The Raw Data '!C25 -> 11145 | P26: ='The Raw Data '!D25 -> 14619 | Q26: ='The Raw Data '!E25 -> 15749 | R26: ='The Raw Data '!F25 -> 15485
F27: =(F24-F25)/F26 -> 1.0940347 | G27: =(G24-G25)/G26 -> 0.95894737 | H27: =(H24-H25)/H26 -> 0.93074427 | I27: =(I24-I25)/I26 -> 0.94641721 | N27: Number of shares | O27: ='The Raw Data '!C26 -> 7040 | P27: ='The Raw Data '!D26 -> 7040 | Q27: ='The Raw Data '!E26 -> 7040 | R27: ='The Raw Data '!F26 -> 7040
N28: Dividend paid | O28: ='The Raw Data '!C27 -> 7047 | P28: ='The Raw Data '!D27 -> 7252 | Q28: ='The Raw Data '!E27 -> 7616 | R28: ='The Raw Data '!F27 -> 7952
C29: Efficiency Ratios
C30: Inventory Turnover Days | D30: Inventory x 365 days Cost of sales | E30: inventory | F30: =O25 -> 3266 | G30: =P25 -> 3414 | H30: =Q25 -> 4233 | I30: =R25 -> 4424
E31: Cost of sales | F31: =O11 -> 13433 | G31: =P11 -> 15357 | H31: =Q11 -> 18000 | I31: =R11 -> 18520
F32: 365 | G32: 365 | H32: 365 | I32: 365 | N32: Summary of ratios | O32: 2020 | P32: 2021 | Q32: 2022 | R32: 2023
F33: =(F30*F32)/F31 -> 88.743393 | G33: =(G30*G32)/G31 -> 81.142801 | H33: =(H30*H32)/H31 -> 85.835833 | I33: =(I30*I32)/I31 -> 87.190065 | N33: profitability
N34: ROCE | O34: =F9 -> 0.12376708 | P34: =G9 -> 0.13854094 | Q34: =H9 -> 0.14935856 | R34: =I9 -> 0.15257918
N35: Operating profit margin | O35: =F13 -> 0.27252075 | P35: =G13 -> 0.26666667 | Q35: =H13 -> 0.25367408 | R35: =I13 -> 0.24721336
C36: Receivables turnover days | D36: Receivables x 365 days Total Revenue | E36: Average receivables | F36: =O24 -> 3144 | G36: =P24 -> 3512 | H36: =Q24 -> 3487 | I36: =R24 -> 3410 | N36: return on assets | O36: =F17 -> 0.11231012 | P36: =G17 -> 0.082328253 | Q36: =H17 -> 0.10317691 | R36: =I17 -> 0.10954628
E37: Total Revenue | F37: =O7 -> 33014 | G37: =P7 -> 38655 | H37: =Q7 -> 43004 | I37: =R7 -> 45754 | N37: Efficiency
F38: 365 | G38: 366 | H38: 367 | I38: 368 | N38: Inventory Turnover days | O38: =F33 -> 88.743393 | P38: =G33 -> 81.142801 | Q38: =H33 -> 85.835833 | R38: =I33 -> 87.190065
F39: =(F36*F38)/F37 -> 34.759799 | G39: =(G36*G38)/G37 -> 33.25293 | H39: =(H36*H38)/H37 -> 29.758371 | I39: =(I36*I38)/I37 -> 27.426673 | N39: receivable Turnover days | O39: =F39 -> 34.759799 | P39: =G39 -> 33.25293 | Q39: =H39 -> 29.758371 | R39: =I39 -> 27.426673
N40: liquidity
C41: Gearing Ratios | N41: Current ratio | O41: =F22 -> 1.317718 | P41: =G22 -> 1.1300752 | Q41: =H22 -> 1.1453559 | R41: =I22 -> 1.1341055
C42: Interest Coverage (Number of times) | D42: Operating Profit Interest on Loan (Finance costs) | E42: Operating profit | F42: =O8 -> 8997 | G42: =P8 -> 10308 | H42: =Q8 -> 10909 | I42: =R8 -> 11311 | N42: Quick ratio | O42: =F27 -> 1.0940347 | P42: =G27 -> 0.95894737 | Q42: =H27 -> 0.93074427 | R42: =I27 -> 0.94641721
E43: Interest on loan | F43: =O9 -> 1437 | G43: =P9 -> 1597 | H43: =Q9 -> 882 | I43: =R9 -> 1527 | N43: Gearing Ratio
F44: =F42/F43 -> 6.2609603 | G44: =G42/G43 -> 6.4546024 | H44: =H42/H43 -> 12.368481 | I44: =I42/I43 -> 7.4073346 | N44: interest cover | O44: =F44 -> 6.2609603 | P44: =G44 -> 6.4546024 | Q44: =H44 -> 12.368481 | R44: =I44 -> 7.4073346
N45: gearing ratio | O45: =F48 -> 0.70721508 | P45: =G48 -> 0.66587818 | Q45: =H48 -> 0.64640808 | R45: =I48 -> 0.62929488
...

Sheet Charts
O1: The Coca-Cola Company: Financial Performance Analysis (2020–2023)
